Workbook

Sheet Actual Expenses
B2: Start Date | C2: 45536
B4: Actual Operating Expenses
B5: Account # | C5: Department | D5: Description | E5: =$C$2 -> 45536 | F5: =EDATE(E5,1) -> 45566 | G5: =EDATE(F5,1) -> 45597 | H5: =EDATE(G5,1) -> 45627
B6: 11256 | C6: Marketing | D6: Paid Ads | E6: 22992 | F6: 24001 | G6: 26558 | H6: 25446
B7: 11257 | C7: Marketing | D7: Infuencers | E7: 53326 | F7: 54223 | G7: 51000 | H7: 50000
B8: 11259 | C8: Engineering | D8: Consulting | E8: 35888 | F8: 36880 | G8: 37995 | H8: 40000
B9: 11260 | C9: Engineering | D9: Travel | E9: 87942 | F9: 85224 | G9: 82469 | H9: 81005
B10: 11263 | C10: Support | D10: Software | E10: 92622 | F10: 90005 | G10: 87556 | H10: 84522
B11: 11264 | C11: Support | D11: Call Center | E11: 27416 | F11: 26554 | G11: 24330 | H11: 22338
B12: 11267 | C12: HR | D12: Recruiting Events | E12: 41696 | F12: 41696 | G12: 42558 | H12: 45448
B13: 11268 | C13: HR | D13: Meetups | E13: 60285 | F13: 61225 | G13: 68994 | H13: 72410

Sheet Forecast
B2: Best | C2: 0.3 | V2: Scenario | W2: Key Assumptions
B3: Worst | C3: 0.15 | V3: Base Case | W3: Assumes improved cost efficiency through better vendor negotiations, controlled marketing spend, and stable payroll costs.
V4: Best Case | W4: Assumes improved cost efficiency through better vendor negotiations, controlled marketing spend, and stable payroll costs.
B5: 1. live Case (Selected Scenario) | E5: Actuals | I5: Forecast | V5: Worst Case | W5: Assumes increased operating costs driven by inflationary pressure, higher marketing spend, and potential overhead inefficiencies.
B6: =B20 -> Account # | C6: =C20 -> Department | D6: =D20 -> Description | E6: =E20 -> 45536 | F6: =F20 -> 45566 | G6: =G20 -> 45597 | H6: =H20 -> 45627 | I6: =EDATE(H6,1) -> 45658 | J6: =EDATE(I6,1) -> 45689 | K6: =EDATE(J6,1) -> 45717 | L6: =EDATE(K6,1) -> 45748 | M6: =EDATE(L6,1) -> 45778 | N6: =EDATE(M6,1) -> 45809 | O6: =EDATE(N6,1) -> 45839 | P6: =EDATE(O6,1) -> 45870 | ... T6: =EDATE(S6,1) -> 45992 | V6: Live Case | W6: Represents the currently selected operating scenario used for financial evaluation and is dynamically linked to the Income Statement.
B7: =B21 -> 11256 | C7: =C21 -> Marketing | D7: =D21 -> Paid Ads | E7: =E21 -> 22992 | F7: =F21 -> 24001 | G7: =G21 -> 26558 | H7: =H21 -> 25446 | I7: =CHOOSE('Income Statement'!$C$2,Forecast!I21,Forecast!I32,Forecast!I43) -> 26859.761 | J7: =CHOOSE('Income Statement'!$C$2,Forecast!J21,Forecast!J32,Forecast!J43) -> 26922.594 | K7: =CHOOSE('Income Statement'!$C$2,Forecast!K21,Forecast!K32,Forecast!K43) -> 28560.22 | L7: =CHOOSE('Income Statement'!$C$2,Forecast!L21,Forecast!L32,Forecast!L43) -> 28501.432 | M7: =CHOOSE('Income Statement'!$C$2,Forecast!M21,Forecast!M32,Forecast!M43) -> 30101.347 | N7: =CHOOSE('Income Statement'!$C$2,Forecast!N21,Forecast!N32,Forecast!N43) -> 30111.719 | O7: =CHOOSE('Income Statement'!$C$2,Forecast!O21,Forecast!O32,Forecast!O43) -> 31672.189 | P7: =CHOOSE('Income Statement'!$C$2,Forecast!P21,Forecast!P32,Forecast!P43) -> 31683.439 | ... T7: =CHOOSE('Income Statement'!$C$2,Forecast!T21,Forecast!T32,Forecast!T43) -> 34816.87
B8: =B22 -> 11257 | C8: =C22 -> Marketing | D8: =D22 -> Infuencers | E8: =E22 -> 53326 | F8: =F22 -> 54223 | G8: =G22 -> 51000 | H8: =H22 -> 50000 | I8: =CHOOSE('Income Statement'!$C$2,Forecast!I22,Forecast!I33,Forecast!I44) -> 48858.544 | J8: =CHOOSE('Income Statement'!$C$2,Forecast!J22,Forecast!J33,Forecast!J44) -> 47585.966 | K8: =CHOOSE('Income Statement'!$C$2,Forecast!K22,Forecast!K33,Forecast!K44) -> 45844.021 | L8: =CHOOSE('Income Statement'!$C$2,Forecast!L22,Forecast!L33,Forecast!L44) -> 44591.391 | M8: =CHOOSE('Income Statement'!$C$2,Forecast!M22,Forecast!M33,Forecast!M44) -> 42871.655 | N8: =CHOOSE('Income Statement'!$C$2,Forecast!N22,Forecast!N33,Forecast!N44) -> 41659.495 | O8: =CHOOSE('Income Statement'!$C$2,Forecast!O22,Forecast!O33,Forecast!O44) -> 39701.198 | P8: =CHOOSE('Income Statement'!$C$2,Forecast!P22,Forecast!P33,Forecast!P44) -> 38527.277 | ... T8: =CHOOSE('Income Statement'!$C$2,Forecast!T22,Forecast!T33,Forecast!T44) -> 32319.266
B9: =B23 -> 11259 | C9: =C23 -> Engineering | D9: =D23 -> Consulting | E9: =E23 -> 35888 | F9: =F23 -> 36880 | G9: =G23 -> 37995 | H9: =H23 -> 40000 | I9: =CHOOSE('Income Statement'!$C$2,Forecast!I23,Forecast!I34,Forecast!I45) -> 41183.971 | J9: =CHOOSE('Income Statement'!$C$2,Forecast!J23,Forecast!J34,Forecast!J45) -> 42613.672 | K9: =CHOOSE('Income Statement'!$C$2,Forecast!K23,Forecast!K34,Forecast!K45) -> 44036.168 | L9: =CHOOSE('Income Statement'!$C$2,Forecast!L23,Forecast!L34,Forecast!L45) -> 45413.912 | M9: =CHOOSE('Income Statement'!$C$2,Forecast!M23,Forecast!M34,Forecast!M45) -> 46814.567 | N9: =CHOOSE('Income Statement'!$C$2,Forecast!N23,Forecast!N34,Forecast!N45) -> 48215.311 | O9: =CHOOSE('Income Statement'!$C$2,Forecast!O23,Forecast!O34,Forecast!O45) -> 49616.148 | P9: =CHOOSE('Income Statement'!$C$2,Forecast!P23,Forecast!P34,Forecast!P45) -> 51017.052 | ... T9: =CHOOSE('Income Statement'!$C$2,Forecast!T23,Forecast!T34,Forecast!T45) -> 56620.877
B10: =B24 -> 11260 | C10: =C24 -> Engineering | D10: =D24 -> Travel | E10: =E24 -> 87942 | F10: =F24 -> 85224 | G10: =G24 -> 82469 | H10: =H24 -> 81005 | I10: =CHOOSE('Income Statement'!$C$2,Forecast!I24,Forecast!I35,Forecast!I46) -> 78427.892 | J10: =CHOOSE('Income Statement'!$C$2,Forecast!J24,Forecast!J35,Forecast!J46) -> 76178.043 | K10: =CHOOSE('Income Statement'!$C$2,Forecast!K24,Forecast!K35,Forecast!K46) -> 73912.465 | L10: =CHOOSE('Income Statement'!$C$2,Forecast!L24,Forecast!L35,Forecast!L46) -> 71611.91 | M10: =CHOOSE('Income Statement'!$C$2,Forecast!M24,Forecast!M35,Forecast!M46) -> 69331.893 | N10: =CHOOSE('Income Statement'!$C$2,Forecast!N24,Forecast!N35,Forecast!N46) -> 67050.575 | O10: =CHOOSE('Income Statement'!$C$2,Forecast!O24,Forecast!O35,Forecast!O46) -> 64768.401 | P10: =CHOOSE('Income Statement'!$C$2,Forecast!P24,Forecast!P35,Forecast!P46) -> 62480.729 | ... T10: =CHOOSE('Income Statement'!$C$2,Forecast!T24,Forecast!T35,Forecast!T46) -> 53344.816
B11: =B25 -> 11263 | C11: =C25 -> Support | D11: =D25 -> Software | E11: =E25 -> 92622 | F11: =F25 -> 90005 | G11: =G25 -> 87556 | H11: =H25 -> 84522 | I11: =CHOOSE('Income Statement'!$C$2,Forecast!I25,Forecast!I36,Forecast!I47) -> 81916.877 | J11: =CHOOSE('Income Statement'!$C$2,Forecast!J25,Forecast!J36,Forecast!J47) -> 79206.408 | K11: =CHOOSE('Income Statement'!$C$2,Forecast!K25,Forecast!K36,Forecast!K47) -> 76483.45 | L11: =CHOOSE('Income Statement'!$C$2,Forecast!L25,Forecast!L36,Forecast!L47) -> 73792.488 | M11: =CHOOSE('Income Statement'!$C$2,Forecast!M25,Forecast!M36,Forecast!M47) -> 71086.198 | N11: =CHOOSE('Income Statement'!$C$2,Forecast!N25,Forecast!N36,Forecast!N47) -> 68267.761 | O11: =CHOOSE('Income Statement'!$C$2,Forecast!O25,Forecast!O36,Forecast!O47) -> 65623.68 | P11: =CHOOSE('Income Statement'!$C$2,Forecast!P25,Forecast!P36,Forecast!P47) -> 62955.109 | ... T11: =CHOOSE('Income Statement'!$C$2,Forecast!T25,Forecast!T36,Forecast!T47) -> 51987.35
B12: =B26 -> 11264 | C12: =C26 -> Support | D12: =D26 -> Call Center | E12: =E26 -> 27416 | F12: =F26 -> 26554 | G12: =G26 -> 24330 | H12: =H26 -> 22338 | I12: =CHOOSE('Income Statement'!$C$2,Forecast!I26,Forecast!I37,Forecast!I48) -> 20784.677 | J12: =CHOOSE('Income Statement'!$C$2,Forecast!J26,Forecast!J37,Forecast!J48) -> 18966.367 | K12: =CHOOSE('Income Statement'!$C$2,Forecast!K26,Forecast!K37,Forecast!K48) -> 17138.765 | L12: =CHOOSE('Income Statement'!$C$2,Forecast!L26,Forecast!L37,Forecast!L48) -> 15398.473 | M12: =CHOOSE('Income Statement'!$C$2,Forecast!M26,Forecast!M37,Forecast!M48) -> 13625.108 | N12: =CHOOSE('Income Statement'!$C$2,Forecast!N26,Forecast!N37,Forecast!N48) -> 11459.691 | O12: =CHOOSE('Income Statement'!$C$2,Forecast!O26,Forecast!O37,Forecast!O48) -> 10235.714 | P12: =CHOOSE('Income Statement'!$C$2,Forecast!P26,Forecast!P37,Forecast!P48) -> 8271.2763 | ... T12: =CHOOSE('Income Statement'!$C$2,Forecast!T26,Forecast!T37,Forecast!T48) -> 825.90662
B13: =B27 -> 11267 | C13: =C27 -> HR | D13: =D27 -> Recruiting Events | E13: =E27 -> 41696 | F13: =F27 -> 41696 | G13: =G27 -> 42558 | H13: =H27 -> 45448 | I13: =CHOOSE('Income Statement'!$C$2,Forecast!I27,Forecast!I38,Forecast!I49) -> 46256.947 | J13: =CHOOSE('Income Statement'!$C$2,Forecast!J27,Forecast!J38,Forecast!J49) -> 47704.638 | K13: =CHOOSE('Income Statement'!$C$2,Forecast!K27,Forecast!K38,Forecast!K49) -> 49150.171 | L13: =CHOOSE('Income Statement'!$C$2,Forecast!L27,Forecast!L38,Forecast!L49) -> 50452.329 | M13: =CHOOSE('Income Statement'!$C$2,Forecast!M27,Forecast!M38,Forecast!M49) -> 51824.343 | N13: =CHOOSE('Income Statement'!$C$2,Forecast!N27,Forecast!N38,Forecast!N49) -> 53196.599 | O13: =CHOOSE('Income Statement'!$C$2,Forecast!O27,Forecast!O38,Forecast!O49) -> 54569.117 | P13: =CHOOSE('Income Statement'!$C$2,Forecast!P27,Forecast!P38,Forecast!P49) -> 55941.82 | ... T13: =CHOOSE('Income Statement'!$C$2,Forecast!T27,Forecast!T38,Forecast!T49) -> 61433.162
B14: =B28 -> 11268 | C14: =C28 -> HR | D14: =D28 -> Meetups | E14: =E28 -> 60285 | F14: =F28 -> 61225 | G14: =G28 -> 68994 | H14: =H28 -> 72410 | I14: =CHOOSE('Income Statement'!$C$2,Forecast!I28,Forecast!I39,Forecast!I50) -> 76705.607 | J14: =CHOOSE('Income Statement'!$C$2,Forecast!J28,Forecast!J39,Forecast!J50) -> 80731.326 | K14: =CHOOSE('Income Statement'!$C$2,Forecast!K28,Forecast!K39,Forecast!K50) -> 87089.658 | L14: =CHOOSE('Income Statement'!$C$2,Forecast!L28,Forecast!L39,Forecast!L50) -> 90875.73 | M14: =CHOOSE('Income Statement'!$C$2,Forecast!M28,Forecast!M39,Forecast!M50) -> 96948.062 | N14: =CHOOSE('Income Statement'!$C$2,Forecast!N28,Forecast!N39,Forecast!N50) -> 100800.22 | O14: =CHOOSE('Income Statement'!$C$2,Forecast!O28,Forecast!O39,Forecast!O50) -> 106865.98 | P14: =CHOOSE('Income Statement'!$C$2,Forecast!P28,Forecast!P39,Forecast!P50) -> 111036.03 | ... T14: =CHOOSE('Income Statement'!$C$2,Forecast!T28,Forecast!T39,Forecast!T50) -> 131085.88
B19: 1. Best Case (Cost Optimization) | E19: Actuals | I19: Forecast
A20: x | B20: ='Actual Expenses'!B5 -> Account # | C20: ='Actual Expenses'!C5 -> Department | D20: ='Actual Expenses'!D5 -> Description | E20: ='Actual Expenses'!E5 -> 45536 | F20: ='Actual Expenses'!F5 -> 45566 | G20: ='Actual Expenses'!G5 -> 45597 | H20: ='Actual Expenses'!H5 -> 45627 | I20: =EDATE(H20,1) -> 45658 | J20: =EDATE(I20,1) -> 45689 | K20: =EDATE(J20,1) -> 45717 | L20: =EDATE(K20,1) -> 45748 | M20: =EDATE(L20,1) -> 45778 | N20: =EDATE(M20,1) -> 45809 | O20: =EDATE(N20,1) -> 45839 | P20: =EDATE(O20,1) -> 45870 | ... T20: =EDATE(S20,1) -> 45992
B21: ='Actual Expenses'!B6 -> 11256 | C21: ='Actual Expenses'!C6 -> Marketing | D21: ='Actual Expenses'!D6 -> Paid Ads | E21: ='Actual Expenses'!E6 -> 22992 | F21: ='Actual Expenses'!F6 -> 24001 | G21: ='Actual Expenses'!G6 -> 26558 | H21: ='Actual Expenses'!H6 -> 25446 | I21: =I32*(1+$C$2) -> 34917.689 | J21: =J32*(1+$C$2) -> 34999.372 | K21: =K32*(1+$C$2) -> 37128.286 | L21: =L32*(1+$C$2) -> 37051.862 | M21: =M32*(1+$C$2) -> 39131.751 | N21: =N32*(1+$C$2) -> 39145.235 | O21: =O32*(1+$C$2) -> 41173.846 | P21: =P32*(1+$C$2) -> 41188.471 | ... T21: =T32*(1+$C$2) -> 45261.932
B22: ='Actual Expenses'!B7 -> 11257 | C22: ='Actual Expenses'!C7 -> Marketing | D22: ='Actual Expenses'!D7 -> Infuencers | E22: ='Actual Expenses'!E7 -> 53326 | F22: ='Actual Expenses'!F7 -> 54223 | G22: ='Actual Expenses'!G7 -> 51000 | H22: ='Actual Expenses'!H7 -> 50000 | I22: =I33*(1-$C$2) -> 34200.981 | J22: =J33*(1-$C$2) -> 33310.176 | K22: =K33*(1-$C$2) -> 32090.815 | L22: =L33*(1-$C$2) -> 31213.974 | M22: =M33*(1-$C$2) -> 30010.158 | N22: =N33*(1-$C$2) -> 29161.646 | O22: =O33*(1-$C$2) -> 27790.839 | P22: =P33*(1-$C$2) -> 26969.094 | ... T22: =T33*(1-$C$2) -> 22623.486
B23: ='Actual Expenses'!B8 -> 11259 | C23: ='Actual Expenses'!C8 -> Engineering | D23: ='Actual Expenses'!D8 -> Consulting | E23: ='Actual Expenses'!E8 -> 35888 | F23: ='Actual Expenses'!F8 -> 36880 | G23: ='Actual Expenses'!G8 -> 37995 | H23: ='Actual Expenses'!H8 -> 40000 | I23: =I34*(1-$C$2) -> 28828.78 | J23: =J34*(1-$C$2) -> 29829.57 | K23: =K34*(1-$C$2) -> 30825.318 | L23: =L34*(1-$C$2) -> 31789.738 | M23: =M34*(1-$C$2) -> 32770.197 | N23: =N34*(1-$C$2) -> 33750.718 | O23: =O34*(1-$C$2) -> 34731.303 | P23: =P34*(1-$C$2) -> 35711.936 | ... T23: =T34*(1-$C$2) -> 39634.614
B24: ='Actual Expenses'!B9 -> 11260 | C24: ='Actual Expenses'!C9 -> Engineering | D24: ='Actual Expenses'!D9 -> Travel | E24: ='Actual Expenses'!E9 -> 87942 | F24: ='Actual Expenses'!F9 -> 85224 | G24: ='Actual Expenses'!G9 -> 82469 | H24: ='Actual Expenses'!H9 -> 81005 | I24: =I35*(1-$C$2) -> 54899.524 | J24: =J35*(1-$C$2) -> 53324.63 | K24: =K35*(1-$C$2) -> 51738.726 | L24: =L35*(1-$C$2) -> 50128.337 | M24: =M35*(1-$C$2) -> 48532.325 | N24: =N35*(1-$C$2) -> 46935.402 | O24: =O35*(1-$C$2) -> 45337.88 | P24: =P35*(1-$C$2) -> 43736.51 | ... T24: =T35*(1-$C$2) -> 37341.371
B25: ='Actual Expenses'!B10 -> 11263 | C25: ='Actual Expenses'!C10 -> Support | D25: ='Actual Expenses'!D10 -> Software | E25: ='Actual Expenses'!E10 -> 92622 | F25: ='Actual Expenses'!F10 -> 90005 | G25: ='Actual Expenses'!G10 -> 87556 | H25: ='Actual Expenses'!H10 -> 84522 | I25: =I36*(1-$C$2) -> 57341.814 | J25: =J36*(1-$C$2) -> 55444.485 | K25: =K36*(1-$C$2) -> 53538.415 | L25: =L36*(1-$C$2) -> 51654.742 | M25: =M36*(1-$C$2) -> 49760.338 | N25: =N36*(1-$C$2) -> 47787.432 | O25: =O36*(1-$C$2) -> 45936.576 | P25: =P36*(1-$C$2) -> 44068.577 | ... T25: =T36*(1-$C$2) -> 36391.145
B26: ='Actual Expenses'!B11 -> 11264 | C26: ='Actual Expenses'!C11 -> Support | D26: ='Actual Expenses'!D11 -> Call Center | E26: ='Actual Expenses'!E11 -> 27416 | F26: ='Actual Expenses'!F11 -> 26554 | G26: ='Actual Expenses'!G11 -> 24330 | H26: ='Actual Expenses'!H11 -> 22338 | I26: =I37*(1-$C$2) -> 14549.274 | J26: =J37*(1-$C$2) -> 13276.457 | K26: =K37*(1-$C$2) -> 11997.136 | L26: =L37*(1-$C$2) -> 10778.931 | M26: =M37*(1-$C$2) -> 9537.5757 | N26: =N37*(1-$C$2) -> 8021.7835 | O26: =O37*(1-$C$2) -> 7164.9997 | P26: =P37*(1-$C$2) -> 5789.8934 | ... T26: =T37*(1-$C$2) -> 578.13463
B27: ='Actual Expenses'!B12 -> 11267 | C27: ='Actual Expenses'!C12 -> HR | D27: ='Actual Expenses'!D12 -> Recruiting Events | E27: ='Actual Expenses'!E12 -> 41696 | F27: ='Actual Expenses'!F12 -> 41696 | G27: ='Actual Expenses'!G12 -> 42558 | H27: ='Actual Expenses'!H12 -> 45448 | I27: =I38*(1-$C$2) -> 32379.863 | J27: =J38*(1-$C$2) -> 33393.247 | K27: =K38*(1-$C$2) -> 34405.12 | L27: =L38*(1-$C$2) -> 35316.63 | M27: =M38*(1-$C$2) -> 36277.04 | N27: =N38*(1-$C$2) -> 37237.62 | O27: =O38*(1-$C$2) -> 38198.382 | P27: =P38*(1-$C$2) -> 39159.274 | ... T27: =T38*(1-$C$2) -> 43003.214
B28: ='Actual Expenses'!B13 -> 11268 | C28: ='Actual Expenses'!C13 -> HR | D28: ='Actual Expenses'!D13 -> Meetups | E28: ='Actual Expenses'!E13 -> 60285 | F28: ='Actual Expenses'!F13 -> 61225 | G28: ='Actual Expenses'!G13 -> 68994 | H28: ='Actual Expenses'!H13 -> 72410 | I28: =I39*(1-$C$2) -> 53693.925 | J28: =J39*(1-$C$2) -> 56511.928 | K28: =K39*(1-$C$2) -> 60962.76 | L28: =L39*(1-$C$2) -> 63613.011 | M28: =M39*(1-$C$2) -> 67863.644 | N28: =N39*(1-$C$2) -> 70560.152 | O28: =O39*(1-$C$2) -> 74806.187 | P28: =P39*(1-$C$2) -> 77725.223 | ... T28: =T39*(1-$C$2) -> 91760.115
B30: 2. Base Case (Management Plan) | E30: Actuals | I30: Forecast
A31: x | B31: ='Actual Expenses'!B5 -> Account # | C31: ='Actual Expenses'!C5 -> Department | D31: ='Actual Expenses'!D5 -> Description | E31: ='Actual Expenses'!E5 -> 45536 | F31: ='Actual Expenses'!F5 -> 45566 | G31: ='Actual Expenses'!G5 -> 45597 | H31: ='Actual Expenses'!H5 -> 45627 | I31: =EDATE(H31,1) -> 45658 | J31: =EDATE(I31,1) -> 45689 | K31: =EDATE(J31,1) -> 45717 | L31: =EDATE(K31,1) -> 45748 | M31: =EDATE(L31,1) -> 45778 | N31: =EDATE(M31,1) -> 45809 | O31: =EDATE(N31,1) -> 45839 | P31: =EDATE(O31,1) -> 45870 | ... T31: =EDATE(S31,1) -> 45992
B32: ='Actual Expenses'!B6 -> 11256 | C32: ='Actual Expenses'!C6 -> Marketing | D32: ='Actual Expenses'!D6 -> Paid Ads | E32: ='Actual Expenses'!E6 -> 22992 | F32: ='Actual Expenses'!F6 -> 24001 | G32: ='Actual Expenses'!G6 -> 26558 | H32: ='Actual Expenses'!H6 -> 25446 | I32: =_xlfn.FORECAST.ETS(I$31,$E32:H32,$E$31:H$31) -> 26859.761 | J32: =_xlfn.FORECAST.ETS(J$31,$E32:I32,$E$31:I$31) -> 26922.594 | K32: =_xlfn.FORECAST.ETS(K$31,$E32:J32,$E$31:J$31) -> 28560.22 | L32: =_xlfn.FORECAST.ETS(L$31,$E32:K32,$E$31:K$31) -> 28501.432 | M32: =_xlfn.FORECAST.ETS(M$31,$E32:L32,$E$31:L$31) -> 30101.347 | N32: =_xlfn.FORECAST.ETS(N$31,$E32:M32,$E$31:M$31) -> 30111.719 | O32: =_xlfn.FORECAST.ETS(O$31,$E32:N32,$E$31:N$31) -> 31672.189 | P32: =_xlfn.FORECAST.ETS(P$31,$E32:O32,$E$31:O$31) -> 31683.439 | ... T32: =_xlfn.FORECAST.ETS(T$31,$E32:S32,$E$31:S$31) -> 34816.87
B33: ='Actual Expenses'!B7 -> 11257 | C33: ='Actual Expenses'!C7 -> Marketing | D33: ='Actual Expenses'!D7 -> Infuencers | E33: ='Actual Expenses'!E7 -> 53326 | F33: ='Actual Expenses'!F7 -> 54223 | G33: ='Actual Expenses'!G7 -> 51000 | H33: ='Actual Expenses'!H7 -> 50000 | I33: =_xlfn.FORECAST.ETS(I$31,$E33:H33,$E$31:H$31) -> 48858.544 | J33: =_xlfn.FORECAST.ETS(J$31,$E33:I33,$E$31:I$31) -> 47585.966 | K33: =_xlfn.FORECAST.ETS(K$31,$E33:J33,$E$31:J$31) -> 45844.021 | L33: =_xlfn.FORECAST.ETS(L$31,$E33:K33,$E$31:K$31) -> 44591.391 | M33: =_xlfn.FORECAST.ETS(M$31,$E33:L33,$E$31:L$31) -> 42871.655 | N33: =_xlfn.FORECAST.ETS(N$31,$E33:M33,$E$31:M$31) -> 41659.495 | O33: =_xlfn.FORECAST.ETS(O$31,$E33:N33,$E$31:N$31) -> 39701.198 | P33: =_xlfn.FORECAST.ETS(P$31,$E33:O33,$E$31:O$31) -> 38527.277 | ... T33: =_xlfn.FORECAST.ETS(T$31,$E33:S33,$E$31:S$31) -> 32319.266
B34: ='Actual Expenses'!B8 -> 11259 | C34: ='Actual Expenses'!C8 -> Engineering | D34: ='Actual Expenses'!D8 -> Consulting | E34: ='Actual Expenses'!E8 -> 35888 | F34: ='Actual Expenses'!F8 -> 36880 | G34: ='Actual Expenses'!G8 -> 37995 | H34: ='Actual Expenses'!H8 -> 40000 | I34: =_xlfn.FORECAST.ETS(I$31,$E34:H34,$E$31:H$31) -> 41183.971 | J34: =_xlfn.FORECAST.ETS(J$31,$E34:I34,$E$31:I$31) -> 42613.672 | K34: =_xlfn.FORECAST.ETS(K$31,$E34:J34,$E$31:J$31) -> 44036.168 | L34: =_xlfn.FORECAST.ETS(L$31,$E34:K34,$E$31:K$31) -> 45413.912 | M34: =_xlfn.FORECAST.ETS(M$31,$E34:L34,$E$31:L$31) -> 46814.567 | N34: =_xlfn.FORECAST.ETS(N$31,$E34:M34,$E$31:M$31) -> 48215.311 | O34: =_xlfn.FORECAST.ETS(O$31,$E34:N34,$E$31:N$31) -> 49616.148 | P34: =_xlfn.FORECAST.ETS(P$31,$E34:O34,$E$31:O$31) -> 51017.052 | ... T34: =_xlfn.FORECAST.ETS(T$31,$E34:S34,$E$31:S$31) -> 56620.877
B35: ='Actual Expenses'!B9 -> 11260 | C35: ='Actual Expenses'!C9 -> Engineering | D35: ='Actual Expenses'!D9 -> Travel | E35: ='Actual Expenses'!E9 -> 87942 | F35: ='Actual Expenses'!F9 -> 85224 | G35: ='Actual Expenses'!G9 -> 82469 | H35: ='Actual Expenses'!H9 -> 81005 | I35: =_xlfn.FORECAST.ETS(I$31,$E35:H35,$E$31:H$31) -> 78427.892 | J35: =_xlfn.FORECAST.ETS(J$31,$E35:I35,$E$31:I$31) -> 76178.043 | K35: =_xlfn.FORECAST.ETS(K$31,$E35:J35,$E$31:J$31) -> 73912.465 | L35: =_xlfn.FORECAST.ETS(L$31,$E35:K35,$E$31:K$31) -> 71611.91 | M35: =_xlfn.FORECAST.ETS(M$31,$E35:L35,$E$31:L$31) -> 69331.893 | N35: =_xlfn.FORECAST.ETS(N$31,$E35:M35,$E$31:M$31) -> 67050.575 | O35: =_xlfn.FORECAST.ETS(O$31,$E35:N35,$E$31:N$31) -> 64768.401 | P35: =_xlfn.FORECAST.ETS(P$31,$E35:O35,$E$31:O$31) -> 62480.729 | ... T35: =_xlfn.FORECAST.ETS(T$31,$E35:S35,$E$31:S$31) -> 53344.816
B36: ='Actual Expenses'!B10 -> 11263 | C36: ='Actual Expenses'!C10 -> Support | D36: ='Actual Expenses'!D10 -> Software | E36: ='Actual Expenses'!E10 -> 92622 | F36: ='Actual Expenses'!F10 -> 90005 | G36: ='Actual Expenses'!G10 -> 87556 | H36: ='Actual Expenses'!H10 -> 84522 | I36: =_xlfn.FORECAST.ETS(I$31,$E36:H36,$E$31:H$31) -> 81916.877 | J36: =_xlfn.FORECAST.ETS(J$31,$E36:I36,$E$31:I$31) -> 79206.408 | K36: =_xlfn.FORECAST.ETS(K$31,$E36:J36,$E$31:J$31) -> 76483.45 | L36: =_xlfn.FORECAST.ETS(L$31,$E36:K36,$E$31:K$31) -> 73792.488 | M36: =_xlfn.FORECAST.ETS(M$31,$E36:L36,$E$31:L$31) -> 71086.198 | N36: =_xlfn.FORECAST.ETS(N$31,$E36:M36,$E$31:M$31) -> 68267.761 | O36: =_xlfn.FORECAST.ETS(O$31,$E36:N36,$E$31:N$31) -> 65623.68 | P36: =_xlfn.FORECAST.ETS(P$31,$E36:O36,$E$31:O$31) -> 62955.109 | ... T36: =_xlfn.FORECAST.ETS(T$31,$E36:S36,$E$31:S$31) -> 51987.35
B37: ='Actual Expenses'!B11 -> 11264 | C37: ='Actual Expenses'!C11 -> Support | D37: ='Actual Expenses'!D11 -> Call Center | E37: ='Actual Expenses'!E11 -> 27416 | F37: ='Actual Expenses'!F11 -> 26554 | G37: ='Actual Expenses'!G11 -> 24330 | H37: ='Actual Expenses'!H11 -> 22338 | I37: =_xlfn.FORECAST.ETS(I$31,$E37:H37,$E$31:H$31) -> 20784.677 | J37: =_xlfn.FORECAST.ETS(J$31,$E37:I37,$E$31:I$31) -> 18966.367 | K37: =_xlfn.FORECAST.ETS(K$31,$E37:J37,$E$31:J$31) -> 17138.765 | L37: =_xlfn.FORECAST.ETS(L$31,$E37:K37,$E$31:K$31) -> 15398.473 | M37: =_xlfn.FORECAST.ETS(M$31,$E37:L37,$E$31:L$31) -> 13625.108 | N37: =_xlfn.FORECAST.ETS(N$31,$E37:M37,$E$31:M$31) -> 11459.691 | O37: =_xlfn.FORECAST.ETS(O$31,$E37:N37,$E$31:N$31) -> 10235.714 | P37: =_xlfn.FORECAST.ETS(P$31,$E37:O37,$E$31:O$31) -> 8271.2763 | ... T37: =_xlfn.FORECAST.ETS(T$31,$E37:S37,$E$31:S$31) -> 825.90662
B38: ='Actual Expenses'!B12 -> 11267 | C38: ='Actual Expenses'!C12 -> HR | D38: ='Actual Expenses'!D12 -> Recruiting Events | E38: ='Actual Expenses'!E12 -> 41696 | F38: ='Actual Expenses'!F12 -> 41696 | G38: ='Actual Expenses'!G12 -> 42558 | H38: ='Actual Expenses'!H12 -> 45448 | I38: =_xlfn.FORECAST.ETS(I$31,$E38:H38,$E$31:H$31) -> 46256.947 | J38: =_xlfn.FORECAST.ETS(J$31,$E38:I38,$E$31:I$31) -> 47704.638 | K38: =_xlfn.FORECAST.ETS(K$31,$E38:J38,$E$31:J$31) -> 49150.171 | L38: =_xlfn.FORECAST.ETS(L$31,$E38:K38,$E$31:K$31) -> 50452.329 | M38: =_xlfn.FORECAST.ETS(M$31,$E38:L38,$E$31:L$31) -> 51824.343 | N38: =_xlfn.FORECAST.ETS(N$31,$E38:M38,$E$31:M$31) -> 53196.599 | O38: =_xlfn.FORECAST.ETS(O$31,$E38:N38,$E$31:N$31) -> 54569.117 | P38: =_xlfn.FORECAST.ETS(P$31,$E38:O38,$E$31:O$31) -> 55941.82 | ... T38: =_xlfn.FORECAST.ETS(T$31,$E38:S38,$E$31:S$31) -> 61433.162
B39: ='Actual Expenses'!B13 -> 11268 | C39: ='Actual Expenses'!C13 -> HR | D39: ='Actual Expenses'!D13 -> Meetups | E39: ='Actual Expenses'!E13 -> 60285 | F39: ='Actual Expenses'!F13 -> 61225 | G39: ='Actual Expenses'!G13 -> 68994 | H39: ='Actual Expenses'!H13 -> 72410 | I39: =_xlfn.FORECAST.ETS(I$31,$E39:H39,$E$31:H$31) -> 76705.607 | J39: =_xlfn.FORECAST.ETS(J$31,$E39:I39,$E$31:I$31) -> 80731.326 | K39: =_xlfn.FORECAST.ETS(K$31,$E39:J39,$E$31:J$31) -> 87089.658 | L39: =_xlfn.FORECAST.ETS(L$31,$E39:K39,$E$31:K$31) -> 90875.73 | M39: =_xlfn.FORECAST.ETS(M$31,$E39:L39,$E$31:L$31) -> 96948.062 | N39: =_xlfn.FORECAST.ETS(N$31,$E39:M39,$E$31:M$31) -> 100800.22 | O39: =_xlfn.FORECAST.ETS(O$31,$E39:N39,$E$31:N$31) -> 106865.98 | P39: =_xlfn.FORECAST.ETS(P$31,$E39:O39,$E$31:O$31) -> 111036.03 | ... T39: =_xlfn.FORECAST.ETS(T$31,$E39:S39,$E$31:S$31) -> 131085.88
B41: 3. Worst Case (Cost Pressure) | E41: Actuals | I41: Forecast
B42: ='Actual Expenses'!B5 -> Account # | C42: ='Actual Expenses'!C5 -> Department | D42: ='Actual Expenses'!D5 -> Description | E42: ='Actual Expenses'!E5 -> 45536 | F42: ='Actual Expenses'!F5 -> 45566 | G42: ='Actual Expenses'!G5 -> 45597 | H42: ='Actual Expenses'!H5 -> 45627 | I42: =EDATE(H42,1) -> 45658 | J42: =EDATE(I42,1) -> 45689 | K42: =EDATE(J42,1) -> 45717 | L42: =EDATE(K42,1) -> 45748 | M42: =EDATE(L42,1) -> 45778 | N42: =EDATE(M42,1) -> 45809 | O42: =EDATE(N42,1) -> 45839 | P42: =EDATE(O42,1) -> 45870 | ... T42: =EDATE(S42,1) -> 45992
B43: ='Actual Expenses'!B6 -> 11256 | C43: ='Actual Expenses'!C6 -> Marketing | D43: ='Actual Expenses'!D6 -> Paid Ads | E43: ='Actual Expenses'!E6 -> 22992 | F43: ='Actual Expenses'!F6 -> 24001 | G43: ='Actual Expenses'!G6 -> 26558 | H43: ='Actual Expenses'!H6 -> 25446 | I43: =I32*(1-$C$3) -> 22830.797 | J43: =J32*(1-$C$3) -> 22884.205 | K43: =K32*(1-$C$3) -> 24276.187 | L43: =L32*(1-$C$3) -> 24226.217 | M43: =M32*(1-$C$3) -> 25586.145 | N43: =N32*(1-$C$3) -> 25594.961 | O43: =O32*(1-$C$3) -> 26921.361 | P43: =P32*(1-$C$3) -> 26930.923 | ... T43: =T32*(1-$C$3) -> 29594.34
B44: ='Actual Expenses'!B7 -> 11257 | C44: ='Actual Expenses'!C7 -> Marketing | D44: ='Actual Expenses'!D7 -> Infuencers | E44: ='Actual Expenses'!E7 -> 53326 | F44: ='Actual Expenses'!F7 -> 54223 | G44: ='Actual Expenses'!G7 -> 51000 | H44: ='Actual Expenses'!H7 -> 50000 | I44: =I33*(1+$C$3) -> 56187.325 | J44: =J33*(1+$C$3) -> 54723.861 | K44: =K33*(1+$C$3) -> 52720.624 | L44: =L33*(1+$C$3) -> 51280.1 | M44: =M33*(1+$C$3) -> 49302.403 | N44: =N33*(1+$C$3) -> 47908.419 | O44: =O33*(1+$C$3) -> 45656.378 | P44: =P33*(1+$C$3) -> 44306.369 | ... T44: =T33*(1+$C$3) -> 37167.156
B45: ='Actual Expenses'!B8 -> 11259 | C45: ='Actual Expenses'!C8 -> Engineering | D45: ='Actual Expenses'!D8 -> Consulting | E45: ='Actual Expenses'!E8 -> 35888 | F45: ='Actual Expenses'!F8 -> 36880 | G45: ='Actual Expenses'!G8 -> 37995 | H45: ='Actual Expenses'!H8 -> 40000 | I45: =I34*(1+$C$3) -> 47361.567 | J45: =J34*(1+$C$3) -> 49005.722 | K45: =K34*(1+$C$3) -> 50641.593 | L45: =L34*(1+$C$3) -> 52225.999 | M45: =M34*(1+$C$3) -> 53836.753 | N45: =N34*(1+$C$3) -> 55447.607 | O45: =O34*(1+$C$3) -> 57058.57 | P45: =P34*(1+$C$3) -> 58669.609 | ... T45: =T34*(1+$C$3) -> 65114.009
B46: ='Actual Expenses'!B9 -> 11260 | C46: ='Actual Expenses'!C9 -> Engineering | D46: ='Actual Expenses'!D9 -> Travel | E46: ='Actual Expenses'!E9 -> 87942 | F46: ='Actual Expenses'!F9 -> 85224 | G46: ='Actual Expenses'!G9 -> 82469 | H46: ='Actual Expenses'!H9 -> 81005 | I46: =I35*(1+$C$3) -> 90192.075 | J46: =J35*(1+$C$3) -> 87604.75 | K46: =K35*(1+$C$3) -> 84999.335 | L46: =L35*(1+$C$3) -> 82353.697 | M46: =M35*(1+$C$3) -> 79731.677 | N46: =N35*(1+$C$3) -> 77108.161 | O46: =O35*(1+$C$3) -> 74483.661 | P46: =P35*(1+$C$3) -> 71852.838 | ... T46: =T35*(1+$C$3) -> 61346.539
B47: ='Actual Expenses'!B10 -> 11263 | C47: ='Actual Expenses'!C10 -> Support | D47: ='Actual Expenses'!D10 -> Software | E47: ='Actual Expenses'!E10 -> 92622 | F47: ='Actual Expenses'!F10 -> 90005 | G47: ='Actual Expenses'!G10 -> 87556 | H47: ='Actual Expenses'!H10 -> 84522 | I47: =I36*(1+$C$3) -> 94204.408 | J47: =J36*(1+$C$3) -> 91087.369 | K47: =K36*(1+$C$3) -> 87955.967 | L47: =L36*(1+$C$3) -> 84861.361 | M47: =M36*(1+$C$3) -> 81749.127 | N47: =N36*(1+$C$3) -> 78507.925 | O47: =O36*(1+$C$3) -> 75467.232 | P47: =P36*(1+$C$3) -> 72398.376 | ... T47: =T36*(1+$C$3) -> 59785.452
...

Sheet Income Statement
B2: Operating Expenses Scenario | C2: 2
P3: Key Financial KPIs
A4: x | B4: Income Statement Forecast | P4: KPI | Q4: Formula
B5: in USD | C5: =Forecast!I6 -> 45658 | D5: =Forecast!J6 -> 45689 | E5: =Forecast!K6 -> 45717 | F5: =Forecast!L6 -> 45748 | G5: =Forecast!M6 -> 45778 | H5: =Forecast!N6 -> 45809 | I5: =Forecast!O6 -> 45839 | J5: =Forecast!P6 -> 45870 | ... N5: =Forecast!T6 -> 45992 | P5: Total Revenue | Q5: =SUM(C6:N6) -> 9277418.3
B6: Revenue | C6: =C31 -> 704180.23 | D6: =D31 -> 692929.61 | E6: =E31 -> 691959.44 | F6: =F31 -> 679763.25 | G6: =G31 -> 678648.91 | H6: =H31 -> 858383.72 | I6: =I31 -> 853625.72 | J6: =J31 -> 839720.17 | ... N6: =N31 -> 802948.19 | P6: Total Operating Expenses | Q6: =SUM(C15:N15) -> 5063210.5
B7: COGS | C7: =C35 -> 211254.07 | D7: =D35 -> 207878.88 | E7: =E35 -> 207587.83 | F7: =F35 -> 203928.98 | G7: =G35 -> 203594.67 | H7: =H35 -> 257515.11 | I7: =I35 -> 256087.72 | J7: =J35 -> 251916.05 | ... N7: =N35 -> 240884.46 | P7: Operating Profit | Q7: =Q5-Q6 -> 4214207.8
B8: Gross Profit | C8: =C6-C7 -> 492926.16 | D8: =D6-D7 -> 485050.73 | E8: =E6-E7 -> 484371.61 | F8: =F6-F7 -> 475834.28 | G8: =G6-G7 -> 475054.24 | H8: =H6-H7 -> 600868.6 | I8: =I6-I7 -> 597538 | J8: =J6-J7 -> 587804.12 | ... N8: =N6-N7 -> 562063.73 | P8: Operating Margin (%) | Q8: =Q7/Q5 -> 0.45424359
P9: Expense-to-Revenue Ratio | Q9: =Q6/Q5 -> 0.54575641
B10: Operating expenses:
B11: {=_xlfn.UNIQUE(Forecast!C7:C14)} -> Marketing | C11: =SUMIFS(Forecast!I$7:I$14,Forecast!$C$7:$C$14,$B11) -> 75718.305 | D11: =SUMIFS(Forecast!J$7:J$14,Forecast!$C$7:$C$14,$B11) -> 74508.56 | E11: =SUMIFS(Forecast!K$7:K$14,Forecast!$C$7:$C$14,$B11) -> 74404.241 | F11: =SUMIFS(Forecast!L$7:L$14,Forecast!$C$7:$C$14,'Income Statement'!$B11) -> 73092.823 | G11: =SUMIFS(Forecast!M$7:M$14,Forecast!$C$7:$C$14,'Income Statement'!$B11) -> 72973.002 | H11: =SUMIFS(Forecast!N$7:N$14,Forecast!$C$7:$C$14,'Income Statement'!$B11) -> 71771.214 | I11: =SUMIFS(Forecast!O$7:O$14,Forecast!$C$7:$C$14,'Income Statement'!$B11) -> 71373.388 | J11: =SUMIFS(Forecast!P$7:P$14,Forecast!$C$7:$C$14,'Income Statement'!$B11) -> 70210.716 | K11: =SUMIFS(Forecast!Q$7:Q$14,Forecast!$C$7:$C$14,'Income Statement'!$B11) -> 69852.942 | L11: =SUMIFS(Forecast!R$7:R$14,Forecast!$C$7:$C$14,'Income Statement'!$B11) -> 68634.804 | M11: =SUMIFS(Forecast!S$7:S$14,Forecast!$C$7:$C$14,'Income Statement'!$B11) -> 68473.718 | N11: =SUMIFS(Forecast!T$7:T$14,Forecast!$C$7:$C$14,'Income Statement'!$B11) -> 67136.136
B12: Engineering | C12: =SUMIFS(Forecast!I$7:I$14,Forecast!$C$7:$C$14,$B12) -> 119611.86 | D12: =SUMIFS(Forecast!J$7:J$14,Forecast!$C$7:$C$14,'Income Statement'!$B12) -> 118791.72 | E12: =SUMIFS(Forecast!K$7:K$14,Forecast!$C$7:$C$14,'Income Statement'!$B12) -> 117948.63 | F12: =SUMIFS(Forecast!L$7:L$14,Forecast!$C$7:$C$14,'Income Statement'!$B12) -> 117025.82 | G12: =SUMIFS(Forecast!M$7:M$14,Forecast!$C$7:$C$14,'Income Statement'!$B12) -> 116146.46 | H12: =SUMIFS(Forecast!N$7:N$14,Forecast!$C$7:$C$14,'Income Statement'!$B12) -> 115265.89 | I12: =SUMIFS(Forecast!O$7:O$14,Forecast!$C$7:$C$14,'Income Statement'!$B12) -> 114384.55 | J12: =SUMIFS(Forecast!P$7:P$14,Forecast!$C$7:$C$14,'Income Statement'!$B12) -> 113497.78 | K12: =SUMIFS(Forecast!Q$7:Q$14,Forecast!$C$7:$C$14,'Income Statement'!$B12) -> 112614.66 | ... N12: =SUMIFS(Forecast!T$7:T$14,Forecast!$C$7:$C$14,'Income Statement'!$B12) -> 109965.69
B13: Support | C13: =SUMIFS(Forecast!I$7:I$14,Forecast!$C$7:$C$14,$B13) -> 102701.55 | D13: =SUMIFS(Forecast!J$7:J$14,Forecast!$C$7:$C$14,'Income Statement'!$B13) -> 98172.775 | E13: =SUMIFS(Forecast!K$7:K$14,Forecast!$C$7:$C$14,'Income Statement'!$B13) -> 93622.215 | F13: =SUMIFS(Forecast!L$7:L$14,Forecast!$C$7:$C$14,'Income Statement'!$B13) -> 89190.961 | G13: =SUMIFS(Forecast!M$7:M$14,Forecast!$C$7:$C$14,'Income Statement'!$B13) -> 84711.306 | H13: =SUMIFS(Forecast!N$7:N$14,Forecast!$C$7:$C$14,'Income Statement'!$B13) -> 79727.451 | I13: =SUMIFS(Forecast!O$7:O$14,Forecast!$C$7:$C$14,'Income Statement'!$B13) -> 75859.394 | J13: =SUMIFS(Forecast!P$7:P$14,Forecast!$C$7:$C$14,'Income Statement'!$B13) -> 71226.386 | K13: =SUMIFS(Forecast!Q$7:Q$14,Forecast!$C$7:$C$14,'Income Statement'!$B13) -> 66324.567 | ... N13: =SUMIFS(Forecast!T$7:T$14,Forecast!$C$7:$C$14,'Income Statement'!$B13) -> 52813.256
B14: HR | C14: =SUMIFS(Forecast!I$7:I$14,Forecast!$C$7:$C$14,'Income Statement'!$B14) -> 122962.55 | D14: =SUMIFS(Forecast!J$7:J$14,Forecast!$C$7:$C$14,'Income Statement'!$B14) -> 128435.96 | E14: =SUMIFS(Forecast!K$7:K$14,Forecast!$C$7:$C$14,'Income Statement'!$B14) -> 136239.83 | F14: =SUMIFS(Forecast!L$7:L$14,Forecast!$C$7:$C$14,'Income Statement'!$B14) -> 141328.06 | G14: =SUMIFS(Forecast!M$7:M$14,Forecast!$C$7:$C$14,'Income Statement'!$B14) -> 148772.41 | H14: =SUMIFS(Forecast!N$7:N$14,Forecast!$C$7:$C$14,'Income Statement'!$B14) -> 153996.82 | I14: =SUMIFS(Forecast!O$7:O$14,Forecast!$C$7:$C$14,'Income Statement'!$B14) -> 161435.1 | J14: =SUMIFS(Forecast!P$7:P$14,Forecast!$C$7:$C$14,'Income Statement'!$B14) -> 166977.85 | ... N14: =SUMIFS(Forecast!T$7:T$14,Forecast!$C$7:$C$14,'Income Statement'!$B14) -> 192519.04
B15: Total operating expenses | C15: =SUM(C11:C14) -> 420994.27 | D15: =SUM(D11:D14) -> 419909.01 | E15: =SUM(E11:E14) -> 422214.92 | F15: =SUM(F11:F14) -> 420637.67 | G15: =SUM(G11:G14) -> 422603.17 | H15: =SUM(H11:H14) -> 420761.37 | I15: =SUM(I11:I14) -> 423052.43 | J15: =SUM(J11:J14) -> 421912.74 | ... N15: =SUM(N11:N14) -> 422434.13
B16: Operating income | C16: =C8-C15 -> 71931.89 | D16: =D8-D15 -> 65141.711 | E16: =E8-E15 -> 62156.689 | F16: =F8-F15 -> 55196.612 | G16: =G8-G15 -> 52451.067 | H16: =H8-H15 -> 180107.23 | I16: =I8-I15 -> 174485.57 | J16: =J8-J15 -> 165891.38 | ... N16: =N8-N15 -> 139629.6
B18: Other income / (expense), net | C18: =C38 -> 5281.3518 | D18: =D38 -> 5196.9721 | E18: =E38 -> 5189.6958 | F18: =F38 -> 5098.2244 | G18: =G38 -> 5089.8669 | H18: =H38 -> 6437.8779 | I18: =I38 -> 6402.1929 | J18: =J38 -> 6297.9012 | ... N18: =N38 -> 6022.1114
B19: Pre-tax income | C19: =C16-C18 -> 66650.538 | D19: =D16-D18 -> 59944.739 | E19: =E16-E18 -> 56966.993 | F19: =F16-F18 -> 50098.388 | G19: =G16-G18 -> 47361.2 | H19: =H16-H18 -> 173669.36 | I19: =I16-I18 -> 168083.38 | J19: =J16-J18 -> 159593.48 | ... N19: =N16-N18 -> 133607.49
B21: Taxes | C21: =IF(C19>0,C19*$C$40,0) -> 16662.635 | D21: =IF(D19>0,D19*$C$40,0) -> 14986.185 | E21: =IF(E19>0,E19*$C$40,0) -> 14241.748 | F21: =IF(F19>0,F19*$C$40,0) -> 12524.597 | G21: =IF(G19>0,G19*$C$40,0) -> 11840.3 | H21: =IF(H19>0,H19*$C$40,0) -> 43417.339 | I21: =IF(I19>0,I19*$C$40,0) -> 42020.845 | J21: =IF(J19>0,J19*$C$40,0) -> 39898.37 | ... N21: =IF(N19>0,N19*$C$40,0) -> 33401.873
B22: Net Income | C22: =C19-C21 -> 49987.904 | D22: =D19-D21 -> 44958.554 | E22: =E19-E21 -> 42725.245 | F22: =F19-F21 -> 37573.791 | G22: =G19-G21 -> 35520.9 | H22: =H19-H21 -> 130252.02 | I22: =I19-I21 -> 126062.54 | J22: =J19-J21 -> 119695.11 | ... N22: =N19-N21 -> 100205.62
A25: x | B25: Assumptions
B26: Revenue
B27: Customer Acquisition Cost | C27: 30 | D27: 30 | E27: 30 | F27: 30 | G27: 30 | H27: 25 | I27: 25 | J27: 25 | K27: 25 | L27: 25 | M27: 25 | N27: 25
B28: Price | C28: 279 | D28: 279 | E28: 279 | F28: 279 | G28: 279 | H28: 299 | I28: 299 | J28: 299 | K28: 299 | L28: 299 | M28: 299 | N28: 299
B30: Units Sold | C30: =C11/C27 -> 2523.9435 | D30: =D11/D27 -> 2483.6187 | E30: =E11/E27 -> 2480.1414 | F30: =F11/F27 -> 2436.4274 | G30: =G11/G27 -> 2432.4334 | H30: =H11/H27 -> 2870.8485 | I30: =I11/I27 -> 2854.9355 | J30: =J11/J27 -> 2808.4286 | ... N30: =N11/N27 -> 2685.4454
B31: Revenue | C31: =C30*C28 -> 704180.23 | D31: =D30*D28 -> 692929.61 | E31: =E30*E28 -> 691959.44 | F31: =F30*F28 -> 679763.25 | G31: =G30*G28 -> 678648.91 | H31: =H30*H28 -> 858383.72 | I31: =I30*I28 -> 853625.72 | J31: =J30*J28 -> 839720.17 | ... N31: =N30*N28 -> 802948.19
B33: Other
B34: COGS % of Revenue | C34: 0.3 | D34: 0.3 | E34: 0.3 | F34: 0.3 | G34: 0.3 | H34: 0.3 | I34: 0.3 | J34: 0.3 | K34: 0.3 | L34: 0.3 | M34: 0.3 | N34: 0.3
B35: COGS | C35: =C31*C34 -> 211254.07 | D35: =D31*D34 -> 207878.88 | E35: =E31*E34 -> 207587.83 | F35: =F31*F34 -> 203928.98 | G35: =G31*G34 -> 203594.67 | H35: =H31*H34 -> 257515.11 | I35: =I31*I34 -> 256087.72 | J35: =J31*J34 -> 251916.05 | ... N35: =N31*N34 -> 240884.46
B37: Other income / (expense), net % of COGS | C37: 0.025 | D37: 0.025 | E37: 0.025 | F37: 0.025 | G37: 0.025 | H37: 0.025 | I37: 0.025 | J37: 0.025 | K37: 0.025 | L37: 0.025 | M37: 0.025 | N37: 0.025
B38: Other income / (expense), net | C38: =C37*C35 -> 5281.3518 | D38: =D37*D35 -> 5196.9721 | E38: =E37*E35 -> 5189.6958 | F38: =F37*F35 -> 5098.2244 | G38: =G37*G35 -> 5089.8669 | H38: =H37*H35 -> 6437.8779 | I38: =I37*I35 -> 6402.1929 | J38: =J37*J35 -> 6297.9012 | ... N38: =N37*N35 -> 6022.1114
A40: x | B40: Tax Rate | C40: 0.25

Sheet Insights And Recommendations
C2: Insights & Recommendations
C4: Key Insights
C6: • Operating expenses are highly sensitive to changes in marketing and administrative costs.
C8: • The Best Case scenario improves operating profit and margin through better cost efficiency.
C10: • The Worst Case scenario shows margin pressure due to higher operating and overhead costs.
C12: • The Live Case represents the most realistic operating outlook and is used for financial evaluation.
C14: • Scenario-based forecasting helps identify financial risks before costs are incurred.
C16: Management Recommendations
C18: • Focus on controlling variable expenses such as marketing and administrative costs to protect profitability.
C20: • Use scenario analysis during budget planning to evaluate financial outcomes under different assumptions.
C22: • Monitor operating margin as a key performance indicator for cost efficiency.
C24: • Update the Live Case regularly to reflect changes in business conditions and cost assumptions.

Sheet Visuals
B2: in USD | C2: ='Income Statement'!C5 -> 45658 | D2: =EDATE(C2,1) -> 45689 | E2: =EDATE(D2,1) -> 45717 | F2: =EDATE(E2,1) -> 45748 | G2: =EDATE(F2,1) -> 45778 | H2: =EDATE(G2,1) -> 45809 | I2: =EDATE(H2,1) -> 45839 | J2: =EDATE(I2,1) -> 45870 | K2: =EDATE(J2,1) -> 45901 | ... N2: =EDATE(M2,1) -> 45992
B3: Revenue | C3: ='Income Statement'!C6 -> 704180.23 | D3: ='Income Statement'!D6 -> 692929.61 | E3: ='Income Statement'!E6 -> 691959.44 | F3: ='Income Statement'!F6 -> 679763.25 | G3: ='Income Statement'!G6 -> 678648.91 | H3: ='Income Statement'!H6 -> 858383.72 | I3: ='Income Statement'!I6 -> 853625.72 | J3: ='Income Statement'!J6 -> 839720.17 | ... N3: ='Income Statement'!N6 -> 802948.19
B4: Profit Margin | C4: ='Income Statement'!C22/Visuals!C3 -> 0.070987371 | D4: ='Income Statement'!D22/Visuals!D3 -> 0.064881849 | E4: ='Income Statement'!E22/Visuals!E3 -> 0.061745302 | F4: ='Income Statement'!F22/Visuals!F3 -> 0.055274819 | G4: ='Income Statement'!G22/Visuals!G3 -> 0.052340613 | H4: ='Income Statement'!H22/Visuals!H3 -> 0.15174102 | I4: ='Income Statement'!I22/Visuals!I3 -> 0.14767893 | J4: ='Income Statement'!J22/Visuals!J3 -> 0.14254166 | ... N4: ='Income Statement'!N22/Visuals!N3 -> 0.12479712
